<?xml version="1.0" ?>
<robot name="turtlebot3" xmlns:xacro="http://www.ros.org/wiki/xacro">

<material name="silver">
  <color rgba="0.700 0.700 0.700 1.000"/>
</material>

<link name="base_footprint"/>

<joint name="base_joint" type="fixed">
  <parent link="base_footprint"/>
  <child link="base_link"/>
  <origin xyz="0.0 0.0 0.010" rpy="0 0 0"/>
</joint>

<link name="base_link">
  <inertial>
    <origin xyz="8.368053381880458e-07 -1.7610424648219707e-05 0.27252999856366134" rpy="0 0 0"/>
    <mass value="8.34475627832778"/>
    <inertia ixx="0.41971" iyy="0.457952" izz="0.39007" ixy="-1.6e-05" iyz="-2e-06" ixz="-0.0"/>
  </inertial>
  <visual>
    <origin xyz="0 0 0" rpy="0 0 0"/>
    <geometry>
      <mesh filename="file://$(find turtlebot3_description)/meshes/base_link.stl" scale="0.001 0.001 0.001"/>
    </geometry>
    <material name="silver"/>
  </visual>
  <collision>
    <origin xyz="0 0 0" rpy="0 0 0"/>
    <geometry>
      <mesh filename="file://$(find turtlebot3_description)/meshes/base_link.stl" scale="0.001 0.001 0.001"/>
    </geometry>
  </collision>
</link>

<link name="caster_1">
  <inertial>
    <origin xyz="-0.02857352949264516 -0.01151471005681412 -0.03043828110848307" rpy="0 0 0"/>
    <mass value="0.18931422070235698"/>
    <inertia ixx="5.5e-05" iyy="7.4e-05" izz="3.3e-05" ixy="-0.0" iyz="0.0" ixz="0.0"/>
  </inertial>
  <visual>
    <origin xyz="-0.25 -0.2169 -0.058" rpy="0 0 0"/>
    <geometry>
      <mesh filename="file://$(find turtlebot3_description)/meshes/caster_1.stl" scale="0.001 0.001 0.001"/>
    </geometry>
    <material name="silver"/>
  </visual>
  <collision>
    <origin xyz="-0.25 -0.2169 -0.058" rpy="0 0 0"/>
    <geometry>
      <mesh filename="file://$(find turtlebot3_description)/meshes/caster_1.stl" scale="0.001 0.001 0.001"/>
    </geometry>
  </collision>
</link>

<link name="caster_2">
  <inertial>
    <origin xyz="-0.028573529492625066 0.011514701707892594 -0.03043828110848334" rpy="0 0 0"/>
    <mass value="0.18931422070235698"/>
    <inertia ixx="5.5e-05" iyy="7.4e-05" izz="3.3e-05" ixy="-0.0" iyz="0.0" ixz="0.0"/>
  </inertial>
  <visual>
    <origin xyz="-0.25 0.2169 -0.058" rpy="0 0 0"/>
    <geometry>
      <mesh filename="file://$(find turtlebot3_description)/meshes/caster_2.stl" scale="0.001 0.001 0.001"/>
    </geometry>
    <material name="silver"/>
  </visual>
  <collision>
    <origin xyz="-0.25 0.2169 -0.058" rpy="0 0 0"/>
    <geometry>
      <mesh filename="file://$(find turtlebot3_description)/meshes/caster_2.stl" scale="0.001 0.001 0.001"/>
    </geometry>
  </collision>
</link>

<link name="caster_3">
  <inertial>
    <origin xyz="0.028573529330904346 0.01151470170789251 -0.0304382811084827" rpy="0 0 0"/>
    <mass value="0.18931422070235698"/>
    <inertia ixx="5.5e-05" iyy="7.4e-05" izz="3.3e-05" ixy="-0.0" iyz="0.0" ixz="0.0"/>
  </inertial>
  <visual>
    <origin xyz="0.25 0.2169 -0.058" rpy="0 0 0"/>
    <geometry>
      <mesh filename="file://$(find turtlebot3_description)/meshes/caster_3.stl" scale="0.001 0.001 0.001"/>
    </geometry>
    <material name="silver"/>
  </visual>
  <collision>
    <origin xyz="0.25 0.2169 -0.058" rpy="0 0 0"/>
    <geometry>
      <mesh filename="file://$(find turtlebot3_description)/meshes/caster_3.stl" scale="0.001 0.001 0.001"/>
    </geometry>
  </collision>
</link>

<link name="caster_4">
  <inertial>
    <origin xyz="0.02857352933088425 -0.01151471005681412 -0.030438281108482977" rpy="0 0 0"/>
    <mass value="0.18931422070235698"/>
    <inertia ixx="5.5e-05" iyy="7.4e-05" izz="3.3e-05" ixy="-0.0" iyz="0.0" ixz="0.0"/>
  </inertial>
  <visual>
    <origin xyz="0.25 -0.2169 -0.058" rpy="0 0 0"/>
    <geometry>
      <mesh filename="file://$(find turtlebot3_description)/meshes/caster_4.stl" scale="0.001 0.001 0.001"/>
    </geometry>
    <material name="silver"/>
  </visual>
  <collision>
    <origin xyz="0.25 -0.2169 -0.058" rpy="0 0 0"/>
    <geometry>
      <mesh filename="file://$(find turtlebot3_description)/meshes/caster_4.stl" scale="0.001 0.001 0.001"/>
    </geometry>
  </collision>
</link>

<link name="XL430_base_right">
  <inertial>
    <origin xyz="0.015671495929223667 -0.00632193052184804 0.014483637367895638" rpy="0 0 0"/>
    <mass value="0.3239556630537195"/>
    <inertia ixx="5e-05" iyy="7.9e-05" izz="8.6e-05" ixy="0.0" iyz="0.0" ixz="-0.0"/>
  </inertial>
  <visual>
    <origin xyz="0.028 0.198 -0.0855" rpy="0 0 0"/>
    <geometry>
      <mesh filename="file://$(find turtlebot3_description)/meshes/XL430_base_right.stl" scale="0.001 0.001 0.001"/>
    </geometry>
    <material name="silver"/>
  </visual>
  <collision>
    <origin xyz="0.028 0.198 -0.0855" rpy="0 0 0"/>
    <geometry>
      <mesh filename="file://$(find turtlebot3_description)/meshes/XL430_base_right.stl" scale="0.001 0.001 0.001"/>
    </geometry>
  </collision>
</link>

<link name="XL430_motor_right">
  <inertial>
    <origin xyz="-3.045443770730309e-06 -0.002385176775222958 6.646072581162343e-14" rpy="0 0 0"/>
    <mass value="0.011770865349524429"/>
    <inertia ixx="0.0" iyy="1e-06" izz="0.0" ixy="0.0" iyz="0.0" ixz="-0.0"/>
  </inertial>
  <visual>
    <origin xyz="-0.0003 0.2188 -0.1" rpy="0 0 0"/>
    <geometry>
      <mesh filename="file://$(find turtlebot3_description)/meshes/XL430_motor_right.stl" scale="0.001 0.001 0.001"/>
    </geometry>
    <material name="silver"/>
  </visual>
  <collision>
    <origin xyz="-0.0003 0.2188 -0.1" rpy="0 0 0"/>
    <geometry>
      <mesh filename="file://$(find turtlebot3_description)/meshes/XL430_motor_right.stl" scale="0.001 0.001 0.001"/>
    </geometry>
  </collision>
</link>

<link name="wheel_right">
  <inertial>
    <origin xyz="-0.005656851380657197 -0.013437856519626423 -0.005656982696146395" rpy="0 0 0"/>
    <mass value="5.068160827641181"/>
    <inertia ixx="0.014881" iyy="0.029142" izz="0.014881" ixy="0.0" iyz="0.0" ixz="-0.0"/>
  </inertial>
  <visual>
    <origin xyz="-0.005957 0.2233 -0.105657" rpy="0 0 0"/>
    <geometry>
      <mesh filename="file://$(find turtlebot3_description)/meshes/wheel_right.stl" scale="0.001 0.001 0.001"/>
    </geometry>
    <material name="silver"/>
  </visual>
  <collision>
    <origin xyz="-0.005957 0.2233 -0.105657" rpy="0 0 0"/>
    <geometry>
      <mesh filename="file://$(find turtlebot3_description)/meshes/wheel_right.stl" scale="0.001 0.001 0.001"/>
    </geometry>
  </collision>
</link>

<link name="plate">
  <inertial>
    <origin xyz="2.349014429479716e-17 2.217469621428852e-14 0.009999999999990572" rpy="0 0 0"/>
    <mass value="6.078748022419618"/>
    <inertia ixx="0.018932" iyy="0.018932" izz="0.037458" ixy="0.0" iyz="0.0" ixz="0.0"/>
  </inertial>
  <visual>
    <origin xyz="-0.0 0.0 -0.501" rpy="0 0 0"/>
    <geometry>
      <mesh filename="file://$(find turtlebot3_description)/meshes/plate.stl" scale="0.001 0.001 0.001"/>
    </geometry>
    <material name="silver"/>
  </visual>
  <collision>
    <origin xyz="-0.0 0.0 -0.501" rpy="0 0 0"/>
    <geometry>
      <mesh filename="file://$(find turtlebot3_description)/meshes/plate.stl" scale="0.001 0.001 0.001"/>
    </geometry>
  </collision>
</link>

<link name="cobot_body">
  <inertial>
    <origin xyz="-1.3994638513012427e-08 -0.013751224256373267 0.04886454507233462" rpy="0 0 0"/>
    <mass value="12.899764355948896"/>
    <inertia ixx="0.033823" iyy="0.028162" izz="0.035033" ixy="0.0" iyz="-0.000755" ixz="0.0"/>
  </inertial>
  <visual>
    <origin xyz="-0.0 -0.0 -0.521" rpy="0 0 0"/>
    <geometry>
      <mesh filename="file://$(find turtlebot3_description)/meshes/cobot_body.stl" scale="0.001 0.001 0.001"/>
    </geometry>
    <material name="silver"/>
  </visual>
  <collision>
    <origin xyz="-0.0 -0.0 -0.521" rpy="0 0 0"/>
    <geometry>
      <mesh filename="file://$(find turtlebot3_description)/meshes/cobot_body.stl" scale="0.001 0.001 0.001"/>
    </geometry>
  </collision>
</link>

<link name="baseArm">
  <inertial>
    <origin xyz="0.0068967662247284124 2.2561127161268677e-14 0.05549018686904705" rpy="0 0 0"/>
    <mass value="3.4735206294395446"/>
    <inertia ixx="0.004461" iyy="0.004757" izz="0.002424" ixy="0.0" iyz="0.0" ixz="-0.000777"/>
  </inertial>
  <visual>
    <origin xyz="0.0 -0.0 -0.631" rpy="0 0 0"/>
    <geometry>
      <mesh filename="file://$(find turtlebot3_description)/meshes/baseArm.stl" scale="0.001 0.001 0.001"/>
    </geometry>
    <material name="silver"/>
  </visual>
  <collision>
    <origin xyz="0.0 -0.0 -0.631" rpy="0 0 0"/>
    <geometry>
      <mesh filename="file://$(find turtlebot3_description)/meshes/baseArm.stl" scale="0.001 0.001 0.001"/>
    </geometry>
  </collision>
</link>

<link name="lowerArm">
  <inertial>
    <origin xyz="0.03690658575566909 2.2563486026873027e-14 0.06799999999999196" rpy="0 0 0"/>
    <mass value="5.91988968680626"/>
    <inertia ixx="0.0188" iyy="0.019335" izz="0.004161" ixy="0.0" iyz="0.0" ixz="0.0"/>
  </inertial>
  <visual>
    <origin xyz="-0.045 -0.0 -0.716" rpy="0 0 0"/>
    <geometry>
      <mesh filename="file://$(find turtlebot3_description)/meshes/lowerArm.stl" scale="0.001 0.001 0.001"/>
    </geometry>
    <material name="silver"/>
  </visual>
  <collision>
    <origin xyz="-0.045 -0.0 -0.716" rpy="0 0 0"/>
    <geometry>
      <mesh filename="file://$(find turtlebot3_description)/meshes/lowerArm.stl" scale="0.001 0.001 0.001"/>
    </geometry>
  </collision>
</link>

<link name="upperArm">
  <inertial>
    <origin xyz="-0.035022688252996176 2.6167507160751738e-14 0.04949999999999111" rpy="0 0 0"/>
    <mass value="4.802107093668197"/>
    <inertia ixx="0.01014" iyy="0.010584" izz="0.003386" ixy="-0.0" iyz="-0.0" ixz="-0.0"/>
  </inertial>
  <visual>
    <origin xyz="-0.045 -0.0 -0.852" rpy="0 0 0"/>
    <geometry>
      <mesh filename="file://$(find turtlebot3_description)/meshes/upperArm.stl" scale="0.001 0.001 0.001"/>
    </geometry>
    <material name="silver"/>
  </visual>
  <collision>
    <origin xyz="-0.045 -0.0 -0.852" rpy="0 0 0"/>
    <geometry>
      <mesh filename="file://$(find turtlebot3_description)/meshes/upperArm.stl" scale="0.001 0.001 0.001"/>
    </geometry>
  </collision>
</link>

<link name="pitchArm">
  <inertial>
    <origin xyz="0.0344238728691882 2.9930072914790985e-14 0.010576127130799029" rpy="0 0 0"/>
    <mass value="2.265107015236222"/>
    <inertia ixx="0.001595" iyy="0.001803" izz="0.001595" ixy="-0.0" iyz="-0.0" ixz="-0.000324"/>
  </inertial>
  <visual>
    <origin xyz="-0.045 -0.0 -0.951" rpy="0 0 0"/>
    <geometry>
      <mesh filename="file://$(find turtlebot3_description)/meshes/pitchArm.stl" scale="0.001 0.001 0.001"/>
    </geometry>
    <material name="silver"/>
  </visual>
  <collision>
    <origin xyz="-0.045 -0.0 -0.951" rpy="0 0 0"/>
    <geometry>
      <mesh filename="file://$(find turtlebot3_description)/meshes/pitchArm.stl" scale="0.001 0.001 0.001"/>
    </geometry>
  </collision>
</link>

<link name="rollArm">
  <inertial>
    <origin xyz="-4.052314039881821e-15 3.104263161282912e-14 0.04211669650612482" rpy="0 0 0"/>
    <mass value="3.029827579494103"/>
    <inertia ixx="0.0025" iyy="0.002976" izz="0.002441" ixy="0.0" iyz="-0.0" ixz="0.0"/>
  </inertial>
  <visual>
    <origin xyz="-0.09 -0.0 -0.996" rpy="0 0 0"/>
    <geometry>
      <mesh filename="file://$(find turtlebot3_description)/meshes/rollArm.stl" scale="0.001 0.001 0.001"/>
    </geometry>
    <material name="silver"/>
  </visual>
  <collision>
    <origin xyz="-0.09 -0.0 -0.996" rpy="0 0 0"/>
    <geometry>
      <mesh filename="file://$(find turtlebot3_description)/meshes/rollArm.stl" scale="0.001 0.001 0.001"/>
    </geometry>
  </collision>
</link>

<link name="gripperArm">
  <inertial>
    <origin xyz="0.009999999999995929 3.104852866283627e-14 -9.325873406851315e-15" rpy="0 0 0"/>
    <mass value="0.6042068071016569"/>
    <inertia ixx="0.00037" iyy="0.000205" izz="0.000205" ixy="0.0" iyz="0.0" ixz="-0.0"/>
  </inertial>
  <visual>
    <origin xyz="-0.13 -0.0 -1.046" rpy="0 0 0"/>
    <geometry>
      <mesh filename="file://$(find turtlebot3_description)/meshes/gripperArm.stl" scale="0.001 0.001 0.001"/>
    </geometry>
    <material name="silver"/>
  </visual>
  <collision>
    <origin xyz="-0.13 -0.0 -1.046" rpy="0 0 0"/>
    <geometry>
      <mesh filename="file://$(find turtlebot3_description)/meshes/gripperArm.stl" scale="0.001 0.001 0.001"/>
    </geometry>
  </collision>
</link>

<link name="cobot_camera">
  <inertial>
    <origin xyz="0.004999999999995952 3.105530767256797e-14 0.02345781668822733" rpy="0 0 0"/>
    <mass value="0.5631767017754145"/>
    <inertia ixx="0.000724" iyy="0.000514" izz="0.000219" ixy="0.0" iyz="-0.0" ixz="-0.0"/>
  </inertial>
  <visual>
    <origin xyz="-0.15 -0.0 -1.046" rpy="0 0 0"/>
    <geometry>
      <mesh filename="file://$(find turtlebot3_description)/meshes/cobot_camera.stl" scale="0.001 0.001 0.001"/>
    </geometry>
    <material name="silver"/>
  </visual>
  <collision>
    <origin xyz="-0.15 -0.0 -1.046" rpy="0 0 0"/>
    <geometry>
      <mesh filename="file://$(find turtlebot3_description)/meshes/cobot_camera.stl" scale="0.001 0.001 0.001"/>
    </geometry>
  </collision>
</link>

<link name="gripper_base">
  <inertial>
    <origin xyz="0.035566484314994706 -0.00017560554917522554 0.00832682194458001" rpy="0 0 0"/>
    <mass value="0.5510932173775136"/>
    <inertia ixx="0.000508" iyy="0.00049" izz="0.000702" ixy="0.0" iyz="0.0" ixz="-0.000104"/>
  </inertial>
  <visual>
    <origin xyz="-0.16 -0.0 -1.046" rpy="0 0 0"/>
    <geometry>
      <mesh filename="file://$(find turtlebot3_description)/meshes/gripper_base.stl" scale="0.001 0.001 0.001"/>
    </geometry>
    <material name="silver"/>
  </visual>
  <collision>
    <origin xyz="-0.16 -0.0 -1.046" rpy="0 0 0"/>
    <geometry>
      <mesh filename="file://$(find turtlebot3_description)/meshes/gripper_base.stl" scale="0.001 0.001 0.001"/>
    </geometry>
  </collision>
</link>

<link name="gripper_left3">
  <inertial>
    <origin xyz="0.015990426629757803 -0.012967523057076307 0.0034753903195710034" rpy="0 0 0"/>
    <mass value="0.09059526730883281"/>
    <inertia ixx="1.8e-05" iyy="3.3e-05" izz="5e-05" ixy="1.8e-05" iyz="0.0" ixz="-0.0"/>
  </inertial>
  <visual>
    <origin xyz="-0.22039 0.01846 -1.049642" rpy="0 0 0"/>
    <geometry>
      <mesh filename="file://$(find turtlebot3_description)/meshes/gripper_left3.stl" scale="0.001 0.001 0.001"/>
    </geometry>
    <material name="silver"/>
  </visual>
  <collision>
    <origin xyz="-0.22039 0.01846 -1.049642" rpy="0 0 0"/>
    <geometry>
      <mesh filename="file://$(find turtlebot3_description)/meshes/gripper_left3.stl" scale="0.001 0.001 0.001"/>
    </geometry>
  </collision>
</link>

<link name="gripper_left1">
  <inertial>
    <origin xyz="0.011053309239173692 -0.005253691764326537 0.00013660803927972864" rpy="0 0 0"/>
    <mass value="0.09307370524687981"/>
    <inertia ixx="1e-05" iyy="3.5e-05" izz="4.2e-05" ixy="-1.3e-05" iyz="0.0" ixz="0.0"/>
  </inertial>
  <visual>
    <origin xyz="-0.271438 0.051465 -1.053142" rpy="0 0 0"/>
    <geometry>
      <mesh filename="file://$(find turtlebot3_description)/meshes/gripper_left1.stl" scale="0.001 0.001 0.001"/>
    </geometry>
    <material name="silver"/>
  </visual>
  <collision>
    <origin xyz="-0.271438 0.051465 -1.053142" rpy="0 0 0"/>
    <geometry>
      <mesh filename="file://$(find turtlebot3_description)/meshes/gripper_left1.stl" scale="0.001 0.001 0.001"/>
    </geometry>
  </collision>
</link>

<link name="gripper_right3">
  <inertial>
    <origin xyz="0.015990425593987917 0.012967524435841548 0.0035248809278738413" rpy="0 0 0"/>
    <mass value="0.09059526730883281"/>
    <inertia ixx="1.8e-05" iyy="3.3e-05" izz="5e-05" ixy="-1.8e-05" iyz="0.0" ixz="0.0"/>
  </inertial>
  <visual>
    <origin xyz="-0.22039 -0.01822 -1.049642" rpy="0 0 0"/>
    <geometry>
      <mesh filename="file://$(find turtlebot3_description)/meshes/gripper_right3.stl" scale="0.001 0.001 0.001"/>
    </geometry>
    <material name="silver"/>
  </visual>
  <collision>
    <origin xyz="-0.22039 -0.01822 -1.049642" rpy="0 0 0"/>
    <geometry>
      <mesh filename="file://$(find turtlebot3_description)/meshes/gripper_right3.stl" scale="0.001 0.001 0.001"/>
    </geometry>
  </collision>
</link>

<link name="gripper_right1">
  <inertial>
    <origin xyz="0.011053308203403556 0.005253693143092229 -0.00013633679183122638" rpy="0 0 0"/>
    <mass value="0.09307370524687981"/>
    <inertia ixx="1e-05" iyy="3.5e-05" izz="4.2e-05" ixy="1.3e-05" iyz="0.0" ixz="-0.0"/>
  </inertial>
  <visual>
    <origin xyz="-0.271438 -0.051225 -1.053142" rpy="0 0 0"/>
    <geometry>
      <mesh filename="file://$(find turtlebot3_description)/meshes/gripper_right1.stl" scale="0.001 0.001 0.001"/>
    </geometry>
    <material name="silver"/>
  </visual>
  <collision>
    <origin xyz="-0.271438 -0.051225 -1.053142" rpy="0 0 0"/>
    <geometry>
      <mesh filename="file://$(find turtlebot3_description)/meshes/gripper_right1.stl" scale="0.001 0.001 0.001"/>
    </geometry>
  </collision>
</link>

<link name="camera_link">
  <inertial>
    <origin xyz="0.0015201693083259915 -5.299270958027507e-07 0.012451799923456464" rpy="0 0 0"/>
    <mass value="0.3783774808035141"/>
    <inertia ixx="0.000238" iyy="3.5e-05" izz="0.00024" ixy="-0.0" iyz="0.0" ixz="0.0"/>
  </inertial>
  <visual>
    <origin xyz="-0.24 -0.0 -0.611" rpy="0 0 0"/>
    <geometry>
      <mesh filename="file://$(find turtlebot3_description)/meshes/Intel_Realsense_D435.stl" scale="0.001 0.001 0.001"/>
    </geometry>
    <material name="silver"/>
  </visual>
  <collision>
    <origin xyz="-0.24 -0.0 -0.611" rpy="0 0 0"/>
    <geometry>
      <mesh filename="file://$(find turtlebot3_description)/meshes/Intel_Realsense_D435.stl" scale="0.001 0.001 0.001"/>
    </geometry>
  </collision>
</link>

<link name="camera_stand">
  <inertial>
    <origin xyz="8.326672684688674e-17 2.405039069677821e-14 0.05499999999999039" rpy="0 0 0"/>
    <mass value="0.06781913140936957"/>
    <inertia ixx="6.9e-05" iyy="6.9e-05" izz="1e-06" ixy="-0.0" iyz="-0.0" ixz="-0.0"/>
  </inertial>
  <visual>
    <origin xyz="-0.24 0.0 -0.501" rpy="0 0 0"/>
    <geometry>
      <mesh filename="file://$(find turtlebot3_description)/meshes/camera_stand.stl" scale="0.001 0.001 0.001"/>
    </geometry>
    <material name="silver"/>
  </visual>
  <collision>
    <origin xyz="-0.24 0.0 -0.501" rpy="0 0 0"/>
    <geometry>
      <mesh filename="file://$(find turtlebot3_description)/meshes/camera_stand.stl" scale="0.001 0.001 0.001"/>
    </geometry>
  </collision>
</link>

<link name="XL430_base_left">
  <inertial>
    <origin xyz="0.015671495929223758 0.006321930521842017 0.014516362632086596" rpy="0 0 0"/>
    <mass value="0.3239556630537195"/>
    <inertia ixx="5e-05" iyy="7.9e-05" izz="8.6e-05" ixy="-0.0" iyz="0.0" ixz="0.0"/>
  </inertial>
  <visual>
    <origin xyz="0.028 -0.198 -0.0855" rpy="0 0 0"/>
    <geometry>
      <mesh filename="file://$(find turtlebot3_description)/meshes/XL430_base_left.stl" scale="0.001 0.001 0.001"/>
    </geometry>
    <material name="silver"/>
  </visual>
  <collision>
    <origin xyz="0.028 -0.198 -0.0855" rpy="0 0 0"/>
    <geometry>
      <mesh filename="file://$(find turtlebot3_description)/meshes/XL430_base_left.stl" scale="0.001 0.001 0.001"/>
    </geometry>
  </collision>
</link>

<link name="XL430_motor_left">
  <inertial>
    <origin xyz="-3.0454437706458498e-06 0.0023851767752167963 -8.416878305439468e-14" rpy="0 0 0"/>
    <mass value="0.011770865349524429"/>
    <inertia ixx="0.0" iyy="1e-06" izz="0.0" ixy="-0.0" iyz="0.0" ixz="0.0"/>
  </inertial>
  <visual>
    <origin xyz="-0.0003 -0.2188 -0.1" rpy="0 0 0"/>
    <geometry>
      <mesh filename="file://$(find turtlebot3_description)/meshes/XL430_motor_left.stl" scale="0.001 0.001 0.001"/>
    </geometry>
    <material name="silver"/>
  </visual>
  <collision>
    <origin xyz="-0.0003 -0.2188 -0.1" rpy="0 0 0"/>
    <geometry>
      <mesh filename="file://$(find turtlebot3_description)/meshes/XL430_motor_left.stl" scale="0.001 0.001 0.001"/>
    </geometry>
  </collision>
</link>

<link name="wheel_left">
  <inertial>
    <origin xyz="-0.00565685138065711 0.01343785651962029 -0.0056570173038905935" rpy="0 0 0"/>
    <mass value="5.068160827641181"/>
    <inertia ixx="0.014881" iyy="0.029142" izz="0.014881" ixy="-0.0" iyz="0.0" ixz="0.0"/>
  </inertial>
  <visual>
    <origin xyz="-0.005957 -0.2233 -0.105657" rpy="0 0 0"/>
    <geometry>
      <mesh filename="file://$(find turtlebot3_description)/meshes/wheel_left.stl" scale="0.001 0.001 0.001"/>
    </geometry>
    <material name="silver"/>
  </visual>
  <collision>
    <origin xyz="-0.005957 -0.2233 -0.105657" rpy="0 0 0"/>
    <geometry>
      <mesh filename="file://$(find turtlebot3_description)/meshes/wheel_left.stl" scale="0.001 0.001 0.001"/>
    </geometry>
  </collision>
</link>

<joint name="Rigid 5" type="fixed">
  <origin xyz="0.25 0.2169 0.058" rpy="0 0 0"/>
  <parent link="base_link"/>
  <child link="caster_1"/>
</joint>

<joint name="Rigid 6" type="fixed">
  <origin xyz="0.25 -0.2169 0.058" rpy="0 0 0"/>
  <parent link="base_link"/>
  <child link="caster_2"/>
</joint>

<joint name="Rigid 7" type="fixed">
  <origin xyz="-0.25 -0.2169 0.058" rpy="0 0 0"/>
  <parent link="base_link"/>
  <child link="caster_3"/>
</joint>

<joint name="Rigid 8" type="fixed">
  <origin xyz="-0.25 0.2169 0.058" rpy="0 0 0"/>
  <parent link="base_link"/>
  <child link="caster_4"/>
</joint>

<joint name="Rigid 11" type="fixed">
  <origin xyz="-0.028 -0.198 0.0855" rpy="0 0 0"/>
  <parent link="base_link"/>
  <child link="XL430_base_right"/>
</joint>

<joint name="wheel_left_joint" type="continuous">
  <origin xyz="0.0283 0.0208 0.0145" rpy="0 0 0"/>
  <parent link="XL430_base_left"/>
  <child link="XL430_motor_left"/>
  <axis xyz="0.0 1.0 -0.0"/>
</joint>

<joint name="wheel_right_joint" type="continuous">
  <origin xyz="0.0283 -0.0208 0.0145" rpy="0 0 0"/>
  <parent link="XL430_base_right"/>
  <child link="XL430_motor_right"/>
  <axis xyz="-0.0 -1.0 0.0"/>
</joint>

<joint name="Rigid 14" type="fixed">
  <origin xyz="0.005657 -0.0045 0.005657" rpy="0 0 0"/>
  <parent link="XL430_motor_right"/>
  <child link="wheel_right"/>
</joint>

<joint name="Rigid 21" type="fixed">
  <origin xyz="0.0 0.0 0.501" rpy="0 0 0"/>
  <parent link="base_link"/>
  <child link="plate"/>
</joint>

<joint name="Rigid 23" type="fixed">
  <origin xyz="0.0 0.0 0.02" rpy="0 0 0"/>
  <parent link="plate"/>
  <child link="cobot_body"/>
</joint>

<joint name="Revolute 1" type="revolute">
  <origin xyz="-0.0 0.0 0.11" rpy="0 0 0"/>
  <parent link="cobot_body"/>
  <child link="baseArm"/>
  <axis xyz="-0.0 -0.0 1.0"/>
  <limit upper="2.792527" lower="-2.792527" effort="100" velocity="100"/>
</joint>

<joint name="Revolute 2" type="revolute">
  <origin xyz="0.045 0.0 0.085" rpy="0 0 0"/>
  <parent link="baseArm"/>
  <child link="lowerArm"/>
  <axis xyz="1.0 -0.0 0.0"/>
  <limit upper="2.792527" lower="-2.792527" effort="100" velocity="100"/>
</joint>

<joint name="Revolute 3" type="revolute">
  <origin xyz="0.0 0.0 0.136" rpy="0 0 0"/>
  <parent link="lowerArm"/>
  <child link="upperArm"/>
  <axis xyz="-1.0 0.0 -0.0"/>
  <limit upper="2.792527" lower="-2.792527" effort="100" velocity="100"/>
</joint>

<joint name="Revolute 4" type="revolute">
  <origin xyz="0.0 0.0 0.099" rpy="0 0 0"/>
  <parent link="upperArm"/>
  <child link="pitchArm"/>
  <axis xyz="1.0 -0.0 -0.0"/>
  <limit upper="2.792527" lower="-2.792527" effort="100" velocity="100"/>
</joint>

<joint name="Revolute 5" type="revolute">
  <origin xyz="0.045 0.0 0.045" rpy="0 0 0"/>
  <parent link="pitchArm"/>
  <child link="rollArm"/>
  <axis xyz="0.0 0.0 1.0"/>
  <limit upper="2.792527" lower="-2.792527" effort="100" velocity="100"/>
</joint>

<joint name="Revolute 6" type="revolute">
  <origin xyz="0.04 0.0 0.05" rpy="0 0 0"/>
  <parent link="rollArm"/>
  <child link="gripperArm"/>
  <axis xyz="1.0 -0.0 0.0"/>
  <limit upper="2.792527" lower="-2.792527" effort="100" velocity="100"/>
</joint>

<joint name="Rigid 30" type="fixed">
  <origin xyz="0.02 0.0 0.0" rpy="0 0 0"/>
  <parent link="gripperArm"/>
  <child link="cobot_camera"/>
</joint>

<joint name="Rigid 31" type="fixed">
  <origin xyz="0.01 0.0 0.0" rpy="0 0 0"/>
  <parent link="cobot_camera"/>
  <child link="gripper_base"/>
</joint>

<joint name="gripper_controller" type="revolute">
  <origin xyz="0.06039 0.01822 0.003642" rpy="0 0 -0.42"/> <!-- change rpy y to -0.42-->
  <parent link="gripper_base"/>
  <child link="gripper_right3"/>
  <axis xyz="-0.0 -0.0 -1.0"/>
  <limit upper="0.3" lower="-0.7" effort="100" velocity="100"/> <!-- change upper to 0.3 and lower to -0.7-->
</joint>

<joint name="Revolute 36" type="revolute">
  <origin xyz="0.051048 0.033005 0.0035" rpy="0 0 0.42"/> <!-- change rpy y to 0.42-->
  <parent link="gripper_right3"/>
  <child link="gripper_right1"/>
  <axis xyz="0.0 -0.0 1.0"/>
  <limit upper="0.7" lower="-0.3" effort="100" velocity="100"/> <!-- change upper to 0.7 and lower to -0.3-->
  <mimic joint="gripper_controller" multiplier="1" offset="0"/> <!-- add mimic and change multiplier to -1-->
</joint>

<joint name="Revolute 33" type="revolute">
  <origin xyz="0.06039 -0.01846 0.003642" rpy="0 0 0.42"/> <!-- change rpy y to 0.42-->
  <parent link="gripper_base"/>
  <child link="gripper_left3"/>
  <axis xyz="-0.0 -0.0 -1.0"/>
  <limit upper="0.7" lower="-0.3" effort="100" velocity="100"/> <!-- change upper to 0.7 and lower to -0.3-->
  <mimic joint="gripper_controller" multiplier="-1" offset="0"/> <!-- add mimic and change multiplier to -1-->
</joint>

<joint name="Revolute 34" type="revolute">
  <origin xyz="0.051048 -0.033005 0.0035" rpy="0 0 -0.42"/> <!-- change rpy y to -0.42-->
  <parent link="gripper_left3"/>
  <child link="gripper_left1"/>
  <axis xyz="0.0 0.0 1.0"/>
  <limit upper="0.3" lower="-0.7" effort="100" velocity="100"/> <!-- change upper to 0.3 and lower to -0.7-->
  <mimic joint="gripper_controller" multiplier="-1" offset="0"/> <!-- add mimic and change multiplier to 1-->
</joint>

<joint name="Rigid 39" type="fixed">
  <origin xyz="0.0 0.0 0.11" rpy="0 0 0"/>
  <parent link="camera_stand"/>
  <child link="camera_link"/>
</joint>

<joint name="Rigid 40" type="fixed">
  <origin xyz="0.24 0.0 0.501" rpy="0 0 0"/>
  <parent link="base_link"/>
  <child link="camera_stand"/>
</joint>

<joint name="Rigid 42" type="fixed">
  <origin xyz="-0.028 0.198 0.0855" rpy="0 0 0"/>
  <parent link="base_link"/>
  <child link="XL430_base_left"/>
</joint>

<joint name="Rigid 44" type="fixed">
  <origin xyz="0.005657 0.0045 0.005657" rpy="0 0 0"/>
  <parent link="XL430_motor_left"/>
  <child link="wheel_left"/>
</joint>

</robot>
